Workbook
Name IQ_EXPENSE_CODE_: 1056

Sheet LBO
B2: Progress Software LBO
B4: Assumptions | E4: Entry assumptions | H4: Debt assumptions
B5: Revenue | C5: =IS!F8 -> 753409 | E5: LTM EBITDA | F5: =C30 -> 227047 | I5: Amount | J5: Interest Rate | K5: Commitment Fee
B6: Revenue growth | C6: =IS!G9 -> 0.10407228 | E6: Entry multiple | F6: 13 | H6: RCF | I6: 50000 | J6: 0.04 | K6: 0.005
B7: EBITDA margin | C7: =C30/C28 -> 0.30135955 | E7: Exit Multiple | F7: 13 | I7: Amount | J7: Interest Rate | K7: Annual Amortization | L7: xEBITDA
B8: D&A | C8: =(C30-C33)/C28 -> 0.30135955 | E8: Equity purchase value | F8: =F6*F5 -> 2951611 | H8: TLA | I8: =L8/$F$6 -> 0.11538462 | J8: 0.06 | K8: 0.05 | L8: 1.5
B9: NWC change | C9: =-D37/D28 -> 0.094393245 | E9: Sponsor equity | F9: =D16*$F$5 -> 1614291.6 | I9: Amount | J9: Interest Rate | L9: xEBITDA
B10: CapEx | C10: =-D39/D28 -> 0.055032783 | H10: TLB | I10: =L10/$F$6 -> 0.30769231 | J10: 0.09 | L10: 4
I11: Amount | J11: Interest Cash | K11: Interest PIK | L11: xEBITDA
B12: Tax Rate | H12: Mezzanine | I12: =L12/$F$6 -> 0.076923077 | J12: 0.05 | K12: 0.07 | L12: 1
B15: Sources | C15: Amount | D15: xEBITDA | F15: Uses | G15: Amount | H15: xEBITDA
B16: Sponsor equity | C16: =D16*$F$5 -> 1614291.6 | D16: =H22-SUM(D17:D21) -> 7.1099447 | F16: Equity purchase price | G16: =F8 -> 2951611 | H16: =G16/F5 -> 13
B17: Management rollover | C17: =D17*$F$5 -> 68114.1 | D17: 0.3 | F17: Debt restructuring | G17: =H17*$F$5 -> 136228.2 | H17: 0.6
B18: TLA | C18: =D18*$F$5 -> 340570.5 | D18: =L8 -> 1.5 | F18: M&A advisory fees | G18: =H18*$F$5 -> 45409.4 | H18: 0.2
B19: TLB | C19: =D19*$F$5 -> 908188 | D19: =L10 -> 4 | F19: Debt arrangement fee | G19: =H19*$F$5 -> 34057.05 | H19: 0.15
B20: Mezzanine | C20: =D20*$F$5 -> 227047 | D20: =L12 -> 1 | F20: Minimal cash balance | G20: =H20*$F$5 -> 40868.46 | H20: 0.18
B21: Cash on balance sheet | C21: =BS!E4 -> 118077 | D21: =C21/F5 -> 0.52005532 | F21: DSRA balance | G21: =H21*$F$5 -> 68114.1 | H21: 0.3
B22: Total sources | C22: =SUM(C16:C21) -> 3276288.2 | D22: =SUM(D16:D21) -> 14.43 | F22: Total uses | G22: =SUM(G16:G21) -> 3276288.2 | H22: =SUM(H16:H21) -> 14.43
C26: 0 | D26: =C26+1 -> 1 | E26: =D26+1 -> 2 | F26: =E26+1 -> 3 | G26: =F26+1 -> 4 | H26: =G26+1 -> 5
C27: 2024 | D27: =C27+1 -> 2025 | E27: =D27+1 -> 2026 | F27: =E27+1 -> 2027 | G27: =F27+1 -> 2028 | H27: =G27+1 -> 2029
B28: Revenue | C28: =IS!F8 -> 753409 | D28: =IS!G8 -> 831818 | E28: =IS!H8 -> 912696.28 | F28: =IS!I8 -> 996595.12 | G28: =IS!J8 -> 1088499 | H28: =IS!K8 -> 1189193.8
B30: EBITDA | C30: =IS!F35+CFS!F5+CFS!F7 -> 227047 | D30: =IS!G35+CFS!G5+CFS!G7 -> 271772.54 | E30: =IS!H35+CFS!H5+CFS!H7 -> 298113.63 | F30: =IS!I35+CFS!I5+CFS!I7 -> 325455.23 | G30: =IS!J35+CFS!J5+CFS!J7 -> 355433.08 | H30: =IS!K35+CFS!K5+CFS!K7 -> 388304.73
D31: =D30/D28 -> 0.32672115 | E31: =E30/E28 -> 0.32662961 | F31: =F30/F28 -> 0.32656715 | G31: =G30/G28 -> 0.32653504 | H31: =H30/H28 -> 0.32652771
B33: EBT | D33: =IS!G41 -> 63799.433 | E33: =IS!H41 -> 106930.04 | F33: =IS!I41 -> 149366.2 | G33: =IS!J41 -> 179112.05 | H33: =IS!K41 -> 209810.04
B35: Tax expense | D35: =IS!G42 -> 22329.802 | E35: =IS!H42 -> 37425.514 | F35: =IS!I42 -> 52278.17 | G35: =IS!J42 -> 62689.219 | H35: =IS!K42 -> 73433.515
B37: NWC change | D37: =NWC!E27 -> -78518 | E37: =NWC!F27 -> -30013.852 | F37: =NWC!G27 -> -8211.1488 | G37: =NWC!H27 -> -20717.969 | H37: =NWC!I27 -> -11870.321
B39: CapEx | D39: =-('Fixed asset schedule'!H16+'Fixed asset schedule'!H4) -> -45777.259 | E39: =-('Fixed asset schedule'!I16+'Fixed asset schedule'!I4) -> -49638.354 | F39: =-('Fixed asset schedule'!J16+'Fixed asset schedule'!J4) -> -53658.46 | G39: =-('Fixed asset schedule'!K16+'Fixed asset schedule'!K4) -> -58086.455 | H39: =-('Fixed asset schedule'!L16+'Fixed asset schedule'!L4) -> -62961.295
B42: Tax shield | D42: ='Debt Schedule'!C45 -> 39040.431 | E42: ='Debt Schedule'!D45 -> 37951.809 | F42: ='Debt Schedule'!E45 -> 37129.85 | G42: ='Debt Schedule'!F45 -> 36218.487 | H42: ='Debt Schedule'!G45 -> 35283.396
B45: CFADS | D45: =D30-D35-D37+D39-D42 -> 243143.04 | E45: =E30-E35-E37+E39-E42 -> 203111.8 | F45: =F30-F35-F37+F39-F42 -> 190599.9 | G45: =G30-G35-G37+G39-G42 -> 219156.89 | H45: =H30-H35-H37+H39-H42 -> 228496.85
B48: LTM EBITDA | H48: =H30 -> 388304.73
B49: Enterprise value | H49: =H48*F7 -> 5047961.5
B50: (-) Debt | H50: ='Debt Schedule'!G13+'Debt Schedule'!G21+'Debt Schedule'!G32 -> 356570.84
B51: (+) Cash | H51: =CFS!K38 -> 66468.495
B52: Equity Value | H52: =H49-H50+H51 -> 4757859.2
B54: MOIC | H54: =H52/C16 -> 2.9473356
B55: IRR | H55: =(H54)^(1/5)-1 -> 0.24132619
B58: Sensitivity tables
B59: Entry VS Exit Multiple | J59: Debt Size VS Debt Interest
B61: =H54 -> 2.9473356 | C61: 11 | D61: 12 | E61: 13 | F61: 14 | G61: 15 | J61: =H55 -> 0.24132619 | K61: 0.5 | L61: 1 | M61: 1.5 | N61: 2 | O61: 2.5
B62: 11 | C62: 3.4315273 | D62: 2.8698974 | E62: 2.4662519 | F62: 2.1621497 | G62: 1.9248102 | J62: 0.04 | K62: 0.21295974 | L62: 0.22723042 | M62: 0.24155945 | N62: 0.2548116 | O62: 0.26829769
...

Sheet Debt Schedule
C2: 2025 | D2: =C2+1 -> 2026 | E2: =D2+1 -> 2027 | F2: =E2+1 -> 2028 | G2: =F2+1 -> 2029
B3: CFADS | C3: =LBO!D45 -> 243143.04 | D3: =LBO!E45 -> 203111.8 | E3: =LBO!F45 -> 190599.9 | F3: =LBO!G45 -> 219156.89 | G3: =LBO!H45 -> 228496.85
B4: Minimal cash floor | C4: 0 | D4: 0 | E4: 0 | F4: 0 | G4: 0
B5: Amortization | C5: =IF(C18>0, $C$18*LBO!$K$8, 0) -> 17028.525 | D5: =IF(D18>0, $C$18*LBO!$K$8, 0) -> 17028.525 | E5: =IF(E18>0, $C$18*LBO!$K$8, 0) -> 17028.525 | F5: =IF(F18>0, $C$18*LBO!$K$8, 0) -> 17028.525 | G5: =IF(G18>0, $C$18*LBO!$K$8, 0) -> 17028.525
B6: Cashsweep | C6: =C3-C4-C5 -> 226114.52 | D6: =D3-D4-D5 -> 186083.28 | E6: =E3-E4-E5 -> 173571.37 | F6: =F3-F4-F5 -> 202128.36 | G6: =G3-G4-G5 -> 211468.32
B9: RCF
B10: Beginning balance | C10: 0 | D10: =C13 -> 0 | E10: =D13 -> 0 | F10: =E13 -> 0 | G10: =F13 -> 0
B11: Drawdown | C11: =MAX(-C6,0) -> 0 | D11: =MAX(-D6,0) -> 0 | E11: =MAX(-E6,0) -> 0 | F11: =MAX(-F6,0) -> 0 | G11: =MAX(-G6,0) -> 0
B12: Repayment | C12: =MIN(C10, MAX(0, C3-C4-C5)) -> 0 | D12: =MIN(D10, MAX(0, D3-D4-D5)) -> 0 | E12: =MIN(E10, MAX(0, E3-E4-E5)) -> 0 | F12: =MIN(F10, MAX(0, F3-F4-F5)) -> 0 | G12: =MIN(G10, MAX(0, G3-G4-G5)) -> 0
B13: Ending balance | C13: =C10+C11-C12 -> 0 | D13: =D10+D11-D12 -> 0 | E13: =E10+E11-E12 -> 0 | F13: =F10+F11-F12 -> 0 | G13: =G10+G11-G12 -> 0
B15: RCF Unused Commitment | C15: =LBO!$I$6-'Debt Schedule'!C13 -> 50000 | D15: =LBO!$I$6-'Debt Schedule'!D13 -> 50000 | E15: =LBO!$I$6-'Debt Schedule'!E13 -> 50000 | F15: =LBO!$I$6-'Debt Schedule'!F13 -> 50000 | G15: =LBO!$I$6-'Debt Schedule'!G13 -> 50000
B17: TLA
B18: Beginning balance | C18: =LBO!C18 -> 340570.5 | D18: =C21 -> 266256.76 | E18: =D21 -> 210403.47 | F18: =E21 -> 159631.9 | G18: =F21 -> 93279.887
B19: =B5 -> Amortization | C19: =C5 -> 17028.525 | D19: =D5 -> 17028.525 | E19: =E5 -> 17028.525 | F19: =F5 -> 17028.525 | G19: =G5 -> 17028.525
B20: Optional repayment | C20: =MIN(C18-C19, MAX(0, C3 - C4 - C19 - C10 + C12 - C43)) * 50% -> 57285.216 | D20: =MIN(D18-D19, MAX(0, D3 - D4 - D19 - D10 + D12 - D43)) * 50% -> 38824.768 | E20: =MIN(E18-E19, MAX(0, E3 - E4 - E19 - E10 + E12 - E43)) * 50% -> 33743.043 | F20: =MIN(F18-F19, MAX(0, F3 - F4 - F19 - F10 + F12 - F43)) * 50% -> 49323.486 | G20: =MIN(G18-G19, MAX(0, G3 - G4 - G19 - G10 + G12 - G43)) * 50% -> 38125.681
B21: Ending balance | C21: =C18-C19-C20 -> 266256.76 | D21: =D18-D19-D20 -> 210403.47 | E21: =E18-E19-E20 -> 159631.9 | F21: =F18-F19-F20 -> 93279.887 | G21: =G18-G19-G20 -> 38125.681
B23: TLB
B24: Beginning balance | C24: =LBO!$C$19 -> 908188 | D24: =C26 -> 908188 | E24: =D26 -> 908188 | F24: =E26 -> 908188 | G24: =F26 -> 908188
B25: Repayment | C25: 0 | D25: 0 | E25: 0 | F25: 0 | G25: 0
B26: Ending balance | C26: =C24-C25 -> 908188 | D26: =D24-D25 -> 908188 | E26: =E24-E25 -> 908188 | F26: =F24-F25 -> 908188 | G26: =G24-G25 -> 908188
B28: Mezzanine
B29: Beginning balance | C29: =LBO!C20 -> 227047 | D29: =C32 -> 242940.29 | E29: =D32 -> 259946.11 | F29: =E32 -> 278142.34 | G29: =F32 -> 297612.3
B30: Capitalized PIK | C30: =C41 -> 15893.29 | D30: =D41 -> 17005.82 | E30: =E41 -> 18196.228 | F30: =F41 -> 19469.964 | G30: =G41 -> 20832.861
B31: Repayment | G31: =MIN(G29+G30, MAX(0, G6+G11-G12-G19-G20-G25-SUM(G36:G40)-G43)) -> 0
B32: Ending balance | C32: =C29+C30-C31 -> 242940.29 | D32: =D29+D30-D31 -> 259946.11 | E32: =E29+E30-E31 -> 278142.34 | F32: =F29+F30-F31 -> 297612.3 | G32: =G29+G30-G31 -> 318445.16
B35: Interest
B36: Interest RCF | C36: =C13*LBO!$J$6+'Debt Schedule'!C15*LBO!$K$6 -> 250 | D36: =D13*LBO!$J$6+'Debt Schedule'!D15*LBO!$K$6 -> 250 | E36: =E13*LBO!$J$6+'Debt Schedule'!E15*LBO!$K$6 -> 250 | F36: =F13*LBO!$J$6+'Debt Schedule'!F15*LBO!$K$6 -> 250 | G36: =G13*LBO!$J$6+'Debt Schedule'!G15*LBO!$K$6 -> 250
B37: Interest TLA | C37: =((C18+C21)/2)*LBO!$J$8 -> 18204.818 | D37: =((D18+D21)/2)*LBO!$J$8 -> 14299.807 | E37: =((E18+E21)/2)*LBO!$J$8 -> 11101.061 | F37: =((F18+F21)/2)*LBO!$J$8 -> 7587.3535 | G37: =((G18+G21)/2)*LBO!$J$8 -> 3942.167
B38: Interest TLB | C38: =C24*LBO!$J$10 -> 81736.92 | D38: =D24*LBO!$J$10 -> 81736.92 | E38: =E24*LBO!$J$10 -> 81736.92 | F38: =F24*LBO!$J$10 -> 81736.92 | G38: =G24*LBO!$J$10 -> 81736.92
B39: Interest Mezz
B40: Cash | C40: =C29*LBO!$J$12 -> 11352.35 | D40: =D29*LBO!$J$12 -> 12147.015 | E40: =E29*LBO!$J$12 -> 12997.306 | F40: =F29*LBO!$J$12 -> 13907.117 | G40: =G29*LBO!$J$12 -> 14880.615
B41: PIK | C41: =C29*LBO!$K$12 -> 15893.29 | D41: =D29*LBO!$K$12 -> 17005.82 | E41: =E29*LBO!$K$12 -> 18196.228 | F41: =F29*LBO!$K$12 -> 19469.964 | G41: =G29*LBO!$K$12 -> 20832.861
B43: Total Interest Expense | C43: =SUM(C36:C40) -> 111544.09 | D43: =SUM(D36:D40) -> 108433.74 | E43: =SUM(E36:E40) -> 106085.29 | F43: =SUM(F36:F40) -> 103481.39 | G43: =SUM(G36:G40) -> 100809.7
B45: Tax shield | C45: =C43*(IS!$G$43) -> 39040.431 | D45: =D43*(IS!$G$43) -> 37951.809 | E45: =E43*(IS!$G$43) -> 37129.85 | F45: =F43*(IS!$G$43) -> 36218.487 | G45: =G43*(IS!$G$43) -> 35283.396
B47: Cash After the Debt Repayment | C47: =C6+C11-C12-C20-C25-C31-C43 -> 57285.216 | D47: =D6+D11-D12-D20-D25-D31-D43 -> 38824.768 | E47: =E6+E11-E12-E20-E25-E31-E43 -> 33743.043 | F47: =F6+F11-F12-F20-F25-F31-F43 -> 49323.486 | G47: =G6+G11-G12-G20-G25-G31-G43 -> 72532.941
B49: DSCR | C49: =C3/(C40+C38+C37+C36+C19) -> 1.8910952 | D49: =D3/(D40+D38+D37+D36+D19) -> 1.6189075 | E49: =E3/(E40+E38+E37+E36+E19) -> 1.5481602 | F49: =F3/(F40+F38+F37+F36+F19) -> 1.8185797 | G49: =G3/(G40+G38+G37+G36+G19) -> 1.9390724

Sheet IS
B1: Actuals | G1: Projection
A2: Item | B2: 2020 | C2: 2021 | D2: 2022 | E2: 2023 | F2: 2024 | G2: =F2+1 -> 2025 | H2: =G2+1 -> 2026 | I2: =H2+1 -> 2027 | J2: =I2+1 -> 2028 | K2: =J2+1 -> 2029
A3: Revenue: Software licenses | B3: 115249 | C3: 156590 | D3: 188336 | E3: 220789 | F3: 249331 | G3: =F3*(1+G4) -> 275119.11 | H3: =G3*(1+H4) -> 297883.4 | I3: =H3*(1+I4) -> 317601.7 | J3: =I3*(1+J4) -> 338625.25 | K3: =J3*(1+K4) -> 361040.45
A4: % growth | C4: =C3/B3-1 -> 0.35871027 | D4: =D3/C3-1 -> 0.20273325 | E4: =E3/D3-1 -> 0.17231437 | F4: =F3/E3-1 -> 0.12927274 | G4: =F4*(1+G5) -> 0.10342923 | H4: =G4*(1+H5) -> 0.082743381 | I4: =H4*(1+I5) -> 0.066194705 | J4: =I4*(1+J5) -> 0.066194705 | K4: =J4*(1+K5) -> 0.066194705
A5: Revenue growth rate Inc/Decr | D5: =D4/C4-1 -> -0.4348273 | E5: =E4/D4-1 -> -0.15004385 | F5: =F4/E4-1 -> -0.24978549 | G5: =AVERAGE($E$5:$F$5) -> -0.19991467 | H5: -0.2 | I5: -0.2 | J5: 0 | K5: 0
A6: Maintenance and services | B6: 326901 | C6: 374723 | D6: 413677 | E6: 473650 | F6: 504078 | G6: =F6*(1+G7) -> 556698.88 | H6: =G6*(1+H7) -> 614812.88 | I6: =H6*(1+I7) -> 678993.42 | J6: =I6*(1+J7) -> 749873.78 | K6: =J6*(1+K7) -> 828153.38
C7: =C6/B6-1 -> 0.14628894 | D7: =D6/C6-1 -> 0.10395412 | E7: =E6/D6-1 -> 0.14497543 | F7: =F6/E6-1 -> 0.064241529 | G7: =AVERAGE($D$7:$F$7) -> 0.10439036 | H7: =AVERAGE($D$7:$F$7) -> 0.10439036 | I7: =AVERAGE($D$7:$F$7) -> 0.10439036 | J7: =AVERAGE($D$7:$F$7) -> 0.10439036 | K7: =AVERAGE($D$7:$F$7) -> 0.10439036
A8: Total revenue | B8: 442150 | C8: 531313 | D8: 602013 | E8: 694439 | F8: 753409 | G8: =G3+G6 -> 831818 | H8: =H3+H6 -> 912696.28 | I8: =I3+I6 -> 996595.12 | J8: =J3+J6 -> 1088499 | K8: =K3+K6 -> 1189193.8
A9: % growth | C9: =C8/B8-1 -> 0.20165781 | D9: =D8/C8-1 -> 0.13306657 | E9: =E8/D8-1 -> 0.15352825 | F9: =F8/E8-1 -> 0.084917466 | G9: =G8/F8-1 -> 0.10407228 | H9: =H8/G8-1 -> 0.097230743 | I9: =I8/H8-1 -> 0.091924162 | J9: =J8/I8-1 -> 0.092217909 | K9: =K8/J8-1 -> 0.09250793
A10: Costs of revenue: Cost of software licenses | B10: 4473 | C10: 5271 | D10: 10243 | E10: 11153 | F10: 10942 | G10: =G8*G11 -> 11252.09 | H10: =H8*H11 -> 12346.139 | I10: =I8*I11 -> 13481.048 | J10: =J8*J11 -> 14724.242 | K10: =K8*K11 -> 16086.351
B11: =B10/B8 -> 0.010116476 | C11: =C10/C8 -> 0.0099207059 | D11: =D10/D8 -> 0.017014583 | E11: =E10/E8 -> 0.016060446 | F11: =F10/F8 -> 0.01452332 | G11: =AVERAGE($B$11:$F$11) -> 0.013527106 | H11: =AVERAGE($B$11:$F$11) -> 0.013527106 | I11: =AVERAGE($B$11:$F$11) -> 0.013527106 | J11: =AVERAGE($B$11:$F$11) -> 0.013527106 | K11: =AVERAGE($B$11:$F$11) -> 0.013527106
A12: Cost of maintenance and services | B12: 49744 | C12: 58242 | D12: 62177 | E12: 85255 | F12: 90318 | G12: =G8*G13 -> 94503.325 | H12: =H8*H13 -> 103691.95 | I12: =I8*I13 -> 113223.75 | J12: =J8*J13 -> 123665.01 | K12: =K8*K13 -> 135105
B13: =B12/B8 -> 0.11250481 | C13: =C12/C8 -> 0.109619 | D13: =D12/D8 -> 0.10328182 | E13: =E12/E8 -> 0.12276816 | F13: =F12/F8 -> 0.11987911 | G13: =AVERAGE($B$13:$F$13) -> 0.11361058 | H13: =AVERAGE($B$13:$F$13) -> 0.11361058 | I13: =AVERAGE($B$13:$F$13) -> 0.11361058 | J13: =AVERAGE($B$13:$F$13) -> 0.11361058 | K13: =AVERAGE($B$13:$F$13) -> 0.11361058
A14: Amortization of acquired intangibles | B14: 7897 | C14: 14936 | D14: 22076 | E14: 30169 | F14: 29222 | G14: =G8*G15 -> 32263.2 | H14: =H8*H15 -> 24447.82 | I14: =I8*I15 -> 21712.19 | J14: =J8*J15 -> 20448.945 | K14: =K8*K15 -> 22340.635
B15: =B14/B8 -> 0.017860455 | C15: =C14/C8 -> 0.02811149 | D15: =D14/D8 -> 0.036670304 | E15: =E14/E8 -> 0.043443701 | F15: =F14/F8 -> 0.03878637 | G15: 0.03878637 | H15: 0.02678637 | I15: 0.02178637 | J15: 0.01878637 | K15: 0.01878637
A16: Total COGS | B16: 62114 | C16: 78449 | D16: 94496 | E16: 126577 | F16: 130482 | G16: =G12+G10+G14 -> 138018.62 | H16: =H12+H10+H14 -> 140485.91 | I16: =I12+I10+I14 -> 148416.99 | J16: =J12+J10+J14 -> 158838.19 | K16: =K12+K10+K14 -> 173531.99
A18: Gross profit | B18: 380036 | C18: 452864 | D18: 507517 | E18: 567862 | F18: 622927 | G18: =G8-G16 -> 693799.38 | H18: =H8-H16 -> 772210.36 | I18: =I8-I16 -> 848178.13 | J18: =J8-J16 -> 929660.84 | K18: =K8-K16 -> 1015661.8
A19: OpEx
A21: Sales and marketing | B21: 100113 | C21: 125890 | D21: 140760 | E21: 156076 | F21: 164570 | G21: =G22*G8 -> 189715.23 | H21: =H22*H8 -> 208161.38 | I21: =I22*I8 -> 227296.45 | J21: =J22*J8 -> 248257.25 | K21: =K22*K8 -> 271223.01
B22: =B21/B8 -> 0.22642316 | C22: =C21/C8 -> 0.23694131 | D22: =D21/D8 -> 0.23381555 | E22: =E21/E8 -> 0.2247512 | F22: =F21/F8 -> 0.21843381 | G22: =AVERAGE($B$22:$F$22) -> 0.22807301 | H22: =AVERAGE($B$22:$F$22) -> 0.22807301 | I22: =AVERAGE($B$22:$F$22) -> 0.22807301 | J22: =AVERAGE($B$22:$F$22) -> 0.22807301 | K22: =AVERAGE($B$22:$F$22) -> 0.22807301
A23: R&D | B23: 88599 | C23: 103338 | D23: 114568 | E23: 132401 | F23: 146342 | G23: =G8*G24 -> 161386.77 | H23: =H8*H24 -> 177078.53 | I23: =I8*I24 -> 193356.32 | J23: =J8*J24 -> 211187.24 | K23: =K8*K24 -> 230723.73
B24: =B23/B8 -> 0.20038222 | C24: =C23/C8 -> 0.19449552 | D24: =D23/D8 -> 0.19030818 | E24: =E23/E8 -> 0.19065893 | F24: =F23/F8 -> 0.19423978 | G24: =AVERAGE($B$24:$F$24) -> 0.19401693 | H24: =AVERAGE($B$24:$F$24) -> 0.19401693 | I24: =AVERAGE($B$24:$F$24) -> 0.19401693 | J24: =AVERAGE($B$24:$F$24) -> 0.19401693 | K24: =AVERAGE($B$24:$F$24) -> 0.19401693
A25: G&A | B25: 54004 | C25: 65128 | D25: 77876 | E25: 83157 | F25: 89518 | G25: =G8*G26 -> 101921.41 | H25: =H8*H26 -> 111831.31 | I25: =I8*I26 -> 122111.31 | J25: =J8*J26 -> 133372.16 | K25: =K8*K26 -> 145710.14
B26: =B25/B8 -> 0.12213955 | C26: =C25/C8 -> 0.12257935 | D26: =D25/D8 -> 0.12935933 | E26: =E25/E8 -> 0.11974702 | F26: =F25/F8 -> 0.11881727 | G26: =AVERAGE($B$26:$G$26) -> 0.1225285 | H26: =AVERAGE($B$26:$G$26) -> 0.1225285 | I26: =AVERAGE($B$26:$G$26) -> 0.1225285 | J26: =AVERAGE($B$26:$G$26) -> 0.1225285 | K26: =AVERAGE($B$26:$G$26) -> 0.1225285
A27: Amortization of acquired intangibles | B27: 20049 | C27: 31996 | D27: 46868 | E27: 66430 | F27: 65290 | G27: =G8*G28 -> 61970.441 | H27: =H8*H28 -> 56313.36 | I27: =I8*I28 -> 46500.567 | J27: =J8*J28 -> 50788.753 | K27: =K8*K28 -> 53923.209
B28: =B27/B8 -> 0.04534434 | C28: =C27/C8 -> 0.060220623 | D28: =D27/D8 -> 0.077852139 | E28: =E27/E8 -> 0.09565995 | F28: =F27/F8 -> 0.086659437 | G28: 0.0745 | H28: 0.0617 | I28: 0.046659437 | J28: 0.046659437 | K28: 0.04534434
A29: Restructuring expenses | B29: 5906 | C29: 6308 | D29: 879 | E29: 8407 | F29: 10454 | G29: 0 | H29: 0 | I29: 0 | J29: 0 | K29: 0
A31: Acquisition-related expenses | B31: 3637 | C31: 4102 | D31: 4603 | E31: 4704 | F31: 17109 | G31: 0 | H31: 0 | I31: 0 | J31: 0 | K31: 0
A33: Cybersecurity | B33: 0 | C33: 0 | D33: 602 | E33: 6164 | F33: 5641 | G33: 6000 | H33: 6000 | I33: 6000 | J33: 6000 | K33: 6000
A34: Total operating expenses | B34: 272308 | C34: 336762 | D34: 375386 | E34: 457339 | F34: 498924 | G34: =G21+G23+G25+G27+G29+G31+G33 -> 520993.86 | H34: =H21+H23+H25+H27+H29+H31+H33 -> 559384.58 | I34: =I21+I23+I25+I27+I29+I31+I33 -> 595264.65 | J34: =J21+J23+J25+J27+J29+J31+J33 -> 649605.4 | K34: =K21+K23+K25+K27+K29+K31+K33 -> 707580.1
A35: Income from operations | B35: 107728 | C35: 116102 | D35: 132131 | E35: 110523 | F35: 124003 | G35: =G18-G34 -> 172805.52 | H35: =H18-H34 -> 212825.78 | I35: =I18-I34 -> 252913.49 | J35: =J18-J34 -> 280055.44 | K35: =K18-K34 -> 308081.75
A36: Interest expense | B36: -10170 | C36: -20045 | D36: -15790 | E36: -30780 | F36: -32012 | G36: =-'Debt Schedule'!C43 -> -111544.09 | H36: =-'Debt Schedule'!D43 -> -108433.74 | I36: =-'Debt Schedule'!E43 -> -106085.29 | J36: =-'Debt Schedule'!F43 -> -103481.39 | K36: =-'Debt Schedule'!G43 -> -100809.7
A37: Interest income and other, net | B37: 1495 | C37: 777 | D37: 1414 | E37: 2538 | F37: 4734 | G37: =$E$37 -> 2538 | H37: =$E$37 -> 2538 | I37: =$E$37 -> 2538 | J37: =$E$37 -> 2538 | K37: =$E$37 -> 2538
A38: FX | B38: -2418 | C38: -1300 | D38: -500 | E38: -2624 | F38: -2461 | G38: 0 | H38: 0 | I38: 0 | J38: 0 | K38: 0
A39: Total other expense, net | B39: -11093 | C39: -20568 | D39: -14876 | E39: -30866 | F39: -29739 | G39: =G36+G37+G38 -> -109006.09 | H39: =H36+H37+H38 -> -105895.74 | I39: =I36+I37+I38 -> -103547.29 | J39: =J36+J37+J38 -> -100943.39 | K39: =K36+K37+K38 -> -98271.702
A41: EBT | B41: 96635 | C41: 95534 | D41: 117255 | E41: 79657 | F41: 94264 | G41: =G35+G39 -> 63799.433 | H41: =H35+H39 -> 106930.04 | I41: =I35+I39 -> 149366.2 | J41: =J35+J39 -> 179112.05 | K41: =K35+K39 -> 209810.04
A42: Tax expense | B42: 16913 | C42: 17114 | D42: 22186 | E42: 9460 | F42: 25826 | G42: =G41*G43 -> 22329.802 | H42: =H41*H43 -> 37425.514 | I42: =I41*I43 -> 52278.17 | J42: =J41*J43 -> 62689.219 | K42: =K41*K43 -> 73433.515
A43: Tax rate | G43: 0.35 | H43: 0.35 | I43: 0.35 | J43: 0.35 | K43: 0.35
A44: Net income | B44: 79722 | C44: 78420 | D44: 95069 | E44: 70197 | F44: 68438 | G44: =G41-G42 -> 41469.632 | H44: =H41-H42 -> 69504.527 | I44: =I41-I42 -> 97088.03 | J44: =J41-J42 -> 116422.83 | K44: =K41-K42 -> 136376.53

Sheet BS
B1: Actual | F1: Projected
A2: Item | B2: 2021 | C2: =B2+1 -> 2022 | D2: =C2+1 -> 2023 | E2: =D2+1 -> 2024 | F2: =E2+1 -> 2025 | G2: =F2+1 -> 2026 | H2: =G2+1 -> 2027 | I2: =H2+1 -> 2028 | J2: =I2+1 -> 2029
A3: Current Assets
A4: Cash and cash equivalents | B4: 155406 | C4: 256277 | D4: 126958 | E4: 118077 | F4: =CFS!G38 -> 108629.4 | G4: =CFS!H38 -> 53035.11 | H4: =CFS!I38 -> 56751.668 | I4: =CFS!J38 -> 50379.356 | J4: =CFS!K38 -> 66468.495
A5: Accounts receivable | B5: 99815 | C5: 97834 | D5: 125825 | E5: 163575 | F5: =NWC!F3 -> 177685.15 | G5: =NWC!G3 -> 194961.6 | H5: =NWC!H3 -> 212883.29 | I5: =NWC!I3 -> 232514.94 | J5: =NWC!J3 -> 254024.41
A6: Unbilled receivables | B6: 25816 | C6: 29158 | D6: 29965 | E6: 34672 | F6: =NWC!F5 -> 41021.161 | G6: =NWC!G5 -> 45009.679 | H6: =NWC!H5 -> 49147.157 | I6: =NWC!I5 -> 53679.405 | J6: =NWC!J5 -> 58645.175
A7: Other current assets | B7: 56771 | C7: 42784 | D7: 48040 | E7: 52489 | F7: =NWC!F7 -> 57951.65 | G7: =NWC!G7 -> 63586.332 | H7: =NWC!H7 -> 69431.452 | I7: =NWC!I7 -> 75834.276 | J7: =NWC!J7 -> 82849.548
A8: Total current assets | B8: 337808 | C8: 426053 | D8: 330788 | E8: 368813 | F8: =SUM(F4:F7) -> 385287.36 | G8: =SUM(G4:G7) -> 356592.73 | H8: =SUM(H4:H7) -> 388213.56 | I8: =SUM(I4:I7) -> 412407.98 | J8: =SUM(J4:J7) -> 461987.63
A9: Long-term unbilled receivables | B9: 17464 | C9: 39936 | D9: 28373 | E9: 28893 | F9: =E9 -> 28893 | G9: =F9 -> 28893 | H9: =G9 -> 28893 | I9: =H9 -> 28893 | J9: =I9 -> 28893
A10: Property and equipment, net | B10: 14345 | C10: 14927 | D10: 15225 | E10: 13746 | F10: ='Fixed asset schedule'!H6 -> 11978.985 | G10: ='Fixed asset schedule'!I6 -> 11455.859 | H10: ='Fixed asset schedule'!J6 -> 10955.578 | I10: ='Fixed asset schedule'!K6 -> 10477.144 | J10: ='Fixed asset schedule'!L6 -> 10019.604
A11: Intangible assets, net | B11: 287185 | C11: 217355 | D11: 354278 | E11: 723571 | F11: ='Fixed asset schedule'!H18 -> 1422109 | G11: ='Fixed asset schedule'!I18 -> 1372462.5 | H11: ='Fixed asset schedule'!J18 -> 1330337.3 | I11: ='Fixed asset schedule'!K18 -> 1295629.6 | J11: ='Fixed asset schedule'!L18 -> 1268282.1
A12: Goodwill | B12: 671152 | C12: 671037 | D12: 832101 | E12: 1292177 | F12: =E12 -> 1292177 | G12: =F12 -> 1292177 | H12: =G12 -> 1292177 | I12: =H12 -> 1292177 | J12: =I12 -> 1292177
A13: Right-of-use lease assets | B13: 25253 | C13: 17574 | D13: 18711 | E13: 30894 | F13: =E13 -> 30894 | G13: =F13 -> 30894 | H13: =G13 -> 30894 | I13: =H13 -> 30894 | J13: =I13 -> 30894
A14: Deferred tax assets | B14: 1415 | C14: 11765 | D14: 15052 | E14: 56179 | F14: 0 | G14: 0 | H14: 0 | I14: 0 | J14: =I14 -> 0
A15: Other assets | B15: 8915 | C15: 12832 | D15: 8255 | E15: 12693 | F15: =NWC!F30 -> 13897.403 | G15: =NWC!G30 -> 15248.658 | H15: =NWC!H30 -> 16650.378 | I15: =NWC!I30 -> 18185.841 | J15: =NWC!J30 -> 19868.176
A16: Total assets | B16: 1363537 | C16: 1411479 | D16: 1602783 | E16: 2526966 | F16: =SUM(F9:F15) -> 2799949.4 | G16: =SUM(G9:G15) -> 2751131 | H16: =SUM(H9:H15) -> 2709907.2 | I16: =SUM(I9:I15) -> 2676256.6 | J16: =SUM(J9:J15) -> 2650133.9
A17: Current Liabilities
A18: Current portion of long-term debt, net | B18: 25767 | C18: 6234 | D18: 13109 | E18: 0 | F18: ='Debt Schedule'!C19+'Debt Schedule'!C25+'Debt Schedule'!C31 -> 17028.525 | G18: ='Debt Schedule'!D19+'Debt Schedule'!D25+'Debt Schedule'!D31 -> 17028.525 | H18: ='Debt Schedule'!E19+'Debt Schedule'!E25+'Debt Schedule'!E31 -> 17028.525 | I18: ='Debt Schedule'!F19+'Debt Schedule'!F25+'Debt Schedule'!F31 -> 17028.525 | J18: ='Debt Schedule'!G19+'Debt Schedule'!G25+'Debt Schedule'!G31 -> 17028.525
A19: Accounts payable | B19: 9683 | C19: 9282 | D19: 12371 | E19: 13910 | F19: =NWC!F12 -> 16800.173 | G19: =NWC!G12 -> 17770.548 | H19: =NWC!H12 -> 18088.224 | I19: =NWC!I12 -> 19109.387 | J19: =NWC!J12 -> 20451.167
A20: Accrued compensation and related payroll taxes | B20: 66607 | C20: 59232 | D20: 72058 | E20: 99891 | F20: =NWC!F16 -> 94124.179 | G20: =NWC!G16 -> 108505.74 | H20: =NWC!H16 -> 119055.84 | I20: =NWC!I16 -> 129999.95 | J20: =NWC!J16 -> 141988.27
A21: Dividends payable to stockholders | B21: 7925 | C21: 8115 | D21: 8376 | E21: 0 | F21: 0 | G21: =F21 -> 0 | H21: =G21 -> 0 | I21: =H21 -> 0 | J21: =I21 -> 0
A22: Short-term operating lease liabilities | B22: 7926 | C22: 7471 | D22: 10114 | E22: 9202 | F22: =E22 -> 9202 | G22: =F22 -> 9202 | H22: =G22 -> 9202 | I22: =H22 -> 9202 | J22: =I22 -> 9202
A23: Short-term deferred revenue, net | B23: 205021 | C23: 227670 | D23: 236090 | E23: 332142 | F23: =NWC!F14 -> 390954.46 | G23: =NWC!G14 -> 410713.33 | H23: =NWC!H14 -> 448467.8 | I23: =NWC!I14 -> 478939.58 | J23: =NWC!J14 -> 523245.28
A24: Total current liabilities | B24: 322929 | C24: 318004 | D24: 352118 | E24: 455145 | F24: =SUM(F18:F23) -> 528109.33 | G24: =SUM(G18:G23) -> 563220.14 | H24: =SUM(H18:H23) -> 611842.39 | I24: =SUM(I18:I23) -> 654279.43 | J24: =SUM(J18:J23) -> 711915.25
A25: Non-Current Liabilities
A26: Long-term debt, net | B26: 239992 | C26: 259220 | D26: 356111 | E26: 730000 | F26: ='Debt Schedule'!C21+'Debt Schedule'!C26+'Debt Schedule'!C32 -> 1417385 | G26: ='Debt Schedule'!D21+'Debt Schedule'!D26+'Debt Schedule'!D32 -> 1378537.6 | H26: ='Debt Schedule'!E21+'Debt Schedule'!E26+'Debt Schedule'!E32 -> 1345962.2 | I26: ='Debt Schedule'!F21+'Debt Schedule'!F26+'Debt Schedule'!F32 -> 1299080.2 | J26: ='Debt Schedule'!G21+'Debt Schedule'!G26+'Debt Schedule'!G32 -> 1264758.8
A27: Convertible senior notes, net | B27: 294535 | C27: 352625 | D27: 354772 | E27: 796267 | F27: =E27 -> 796267 | G27: =F27 -> 796267 | H27: =G27 -> 796267 | I27: =H27 -> 796267 | J27: =I27 -> 796267
A28: Long-term operating lease liabilities | B28: 23130 | C28: 15041 | D28: 13000 | E28: 26259 | F28: =E28 -> 26259 | G28: =F28 -> 26259 | H28: =G28 -> 26259 | I28: =H28 -> 26259 | J28: =I28 -> 26259
A29: Long-term deferred revenue, net | B29: 47359 | C29: 54770 | D29: 58946 | E29: 72270 | F29: =F30*IS!G8 -> 75055.101 | G29: =G30*IS!H8 -> 82352.764 | H29: =H30*IS!I8 -> 89922.973 | I29: =I30*IS!J8 -> 98215.481 | J29: =J30*IS!K8 -> 107301.19
B30: =B29/IS!C8 -> 0.089135782 | C30: =C29/IS!D8 -> 0.090978102 | D30: =D29/IS!E8 -> 0.084882905 | E30: =E29/IS!F8 -> 0.095923993 | F30: =AVERAGE($B$30:$E$30) -> 0.090230196 | G30: =AVERAGE($B$30:$E$30) -> 0.090230196 | H30: =AVERAGE($B$30:$E$30) -> 0.090230196 | I30: =AVERAGE($B$30:$E$30) -> 0.090230196 | J30: =AVERAGE($B$30:$E$30) -> 0.090230196
A31: Deferred tax liabilities | B31: 14163 | C31: 4628 | D31: 3574 | E31: 2279 | F31: 0 | G31: =F31 -> 0 | H31: =G31 -> 0 | I31: =H31 -> 0 | J31: =I31 -> 0
A32: Other noncurrent liabilities | B32: 8940 | C32: 8687 | D32: 4547 | E32: 5958 | F32: =AVERAGE($B$32:$E$32) -> 7033 | G32: =AVERAGE($B$32:$E$32) -> 7033 | H32: =AVERAGE($B$32:$E$32) -> 7033 | I32: =AVERAGE($B$32:$E$32) -> 7033 | J32: =AVERAGE($B$32:$E$32) -> 7033
A33: Total non-current liabilities | B33: =SUM(B26:B29,B31,B32) -> 628119 | C33: =SUM(C26:C29,C31,C32) -> 694971 | D33: =SUM(D26:D29,D31,D32) -> 790950 | E33: =SUM(E26:E29,E31,E32) -> 1633033 | F33: =SUM(F26:F29,F31,F32) -> 2321999.1 | G33: =SUM(G26:G29,G31,G32) -> 2290449.3 | H33: =SUM(H26:H29,H31,H32) -> 2265444.2 | I33: =SUM(I26:I29,I31,I32) -> 2226854.7 | J33: =SUM(J26:J29,J31,J32) -> 2201619
A34: Total liabilities | B34: =B24+B33 -> 951048 | C34: =C24+C33 -> 1012975 | D34: =D24+D33 -> 1143068 | E34: =E24+E33 -> 2088178 | F34: =F24+F33 -> 2850108.5 | G34: =G24+G33 -> 2853669.5 | H34: =H24+H33 -> 2877286.6 | I34: =I24+I33 -> 2881134.1 | J34: =J24+J33 -> 2913534.3
A35: Stockholders' Equity
A36: Common stock | B36: 441 | C36: 433 | D36: 438 | E36: 434 | F36: =E36 -> 434 | G36: =F36 -> 434 | H36: =G36 -> 434 | I36: =H36 -> 434 | J36: =I36 -> 434
A37: Additional paid-in capital | B37: 354235 | C37: 331650 | D37: 370579 | E37: 354158 | F37: =E37+CFS!G25+CFS!G26 -> 354158 | G37: =F37+CFS!H25+CFS!H26 -> 354158 | H37: =G37+CFS!I25+CFS!I26 -> 354158 | I37: =H37+CFS!J25+CFS!J26 -> 354158 | J37: =I37+CFS!K25+CFS!K26 -> 354158
A38: Retained earnings | B38: 90256 | C38: 101656 | D38: 120858 | E38: 120405 | F38: =F16-F34-F36-F37-F39 -> -368542.08 | G38: =G16-G34-G36-G37-G39 -> -420921.44 | H38: =H16-H34-H36-H37-H39 -> -485762.35 | I38: =I16-I34-I36-I37-I39 -> -523260.47 | J38: =J16-J34-J36-J37-J39 -> -581783.35
A39: Accumulated other comprehensive loss | B39: -32443 | C39: -35235 | D39: -32160 | E39: -36209 | F39: =E39 -> -36209 | G39: =F39 -> -36209 | H39: =G39 -> -36209 | I39: =H39 -> -36209 | J39: =I39 -> -36209
A40: Total stockholders' equity | B40: 412489 | C40: 398504 | D40: 459715 | E40: 438788 | F40: =SUM(F36:F39) -> -50159.081 | G40: =SUM(G36:G39) -> -102538.44 | H40: =SUM(H36:H39) -> -167379.35 | I40: =SUM(I36:I39) -> -204877.47 | J40: =SUM(J36:J39) -> -263400.35
...

Sheet CFS
B1: Actuals | G1: Projection
B2: 2020 | C2: 2021 | D2: 2022 | E2: 2023 | F2: 2024 | G2: =F2+1 -> 2025 | H2: =G2+1 -> 2026 | I2: =H2+1 -> 2027 | J2: =I2+1 -> 2028 | K2: =J2+1 -> 2029
A3: CFO
A4: Net income | B4: 79722 | C4: 78420 | D4: 95069 | E4: 70197 | F4: 68438 | G4: =IS!G44 -> 41469.632 | H4: =IS!H44 -> 69504.527 | I4: =IS!I44 -> 97088.03 | J4: =IS!J44 -> 116422.83 | K4: =IS!K44 -> 136376.53
A5: Depreciation and amortization of property and equipment | B5: 6144 | C5: 5477 | D5: 5002 | E5: 6345 | F5: 6426 | G5: ='Fixed asset schedule'!H5 -> 4733.3739 | H5: ='Fixed asset schedule'!I5 -> 4526.6659 | I5: ='Fixed asset schedule'!J5 -> 4328.9849 | J5: ='Fixed asset schedule'!K5 -> 4139.9367 | K5: ='Fixed asset schedule'!L5 -> 3959.1443
A7: Amortization of acquired intangibles and other | B7: 28621 | C7: 47507 | D7: 69730 | E7: 96802 | F7: 96618 | G7: =IS!G27+IS!G14 -> 94233.641 | H7: =IS!H27+IS!H14 -> 80761.18 | I7: =IS!I27+IS!I14 -> 68212.757 | J7: =IS!J27+IS!J14 -> 71237.698 | K7: =IS!K27+IS!K14 -> 76263.844
A8: Amortization of debt discount and issuance costs | B8: 0 | C8: 8195 | D8: 2112 | E8: 2147 | F8: 3525 | G8: 0 | H8: 0 | I8: 0 | J8: 0 | K8: 0
A9: Stock-based compensation | B9: 23482 | C9: 29724 | D9: 37094 | E9: 40529 | F9: 46756 | G9: 0 | H9: 0 | I9: 0 | J9: 0 | K9: 0
A10: Non-cash lease expense | B10: 8609 | C10: 10946 | D10: 7781 | E10: 9393 | F10: 11723 | G10: 0 | H10: 0 | I10: 0 | J10: 0 | K10: 0
A11: Changes in accounts receivable | B11: 10682 | C11: -10998 | D11: -27254 | E11: 12119 | F11: -45880 | G11: =NWC!E3-NWC!F3+(NWC!E5-NWC!F5) -> -20459.307 | H11: =NWC!F3-NWC!G3+(NWC!F5-NWC!G5) -> -21264.977 | I11: =NWC!G3-NWC!H3+(NWC!G5-NWC!H5) -> -22059.159 | J11: =NWC!H3-NWC!I3+(NWC!H5-NWC!I5) -> -24163.899 | K11: =NWC!I3-NWC!J3+(NWC!I5-NWC!J5) -> -26475.246
A12: Changes in other assets | B12: 1561 | C12: -15105 | D12: -2214 | E12: -1579 | F12: -2897 | G12: =NWC!E7-NWC!F7 -> -5462.6501 | H12: =NWC!F7-NWC!G7 -> -5634.682 | I12: =NWC!G7-NWC!H7 -> -5845.1203 | J12: =NWC!H7-NWC!I7 -> -6402.8233 | K12: =NWC!I7-NWC!J7 -> -7015.2718
A13: Changes in inventories | B13: 0 | C13: 245 | D13: -1556 | E13: 2489 | F13: 0 | G13: =F13 -> 0 | H13: =G13 -> 0 | I13: =H13 -> 0 | J13: =I13 -> 0 | K13: =J13 -> 0
A14: Changes in accounts payable and accrued liabilities | B14: -4974 | C14: 5486 | D14: -3583 | E14: -1242 | F14: 28922 | G14: =NWC!F12-NWC!E12 -> 2890.1729 | H14: =NWC!G12-NWC!F12 -> 970.37484 | I14: =NWC!H12-NWC!G12 -> 317.67616 | J14: =NWC!I12-NWC!H12 -> 1021.1632 | K14: =NWC!J12-NWC!I12 -> 1341.7796
A15: Changes in deferred revenue, net | B15: 1420 | C15: 30473 | D15: 36268 | E15: -24102 | F15: 16183 | G15: =NWC!F14-NWC!E14 -> 58812.458 | H15: =NWC!G14-NWC!F14 -> 19758.867 | I15: =NWC!H14-NWC!G14 -> 37754.478 | J15: =NWC!I14-NWC!H14 -> 30471.773 | K15: =NWC!J14-NWC!I14 -> 44305.709
A16: Changes in LT Other Assets | D16: =NWC!C32 -> -3917 | E16: =NWC!D32 -> 4577 | F16: =NWC!E32 -> -4438 | G16: =NWC!F32 -> -1204.4031 | H16: =NWC!G32 -> -1351.2548 | I16: =NWC!H32 -> -1401.7201 | J16: =NWC!I32 -> -1535.463 | K16: =NWC!J32 -> -1682.3345
A17: Net cash flows from operating activities | B17: 144847 | C17: 178530 | D17: 192160 | E17: 173920 | F17: 211494 | G17: =SUM(G5:G16) -> 133543.29 | H17: =SUM(H5:H16) -> 77766.174 | I17: =SUM(I5:I16) -> 81307.897 | J17: =SUM(J5:J16) -> 74768.384 | K17: =SUM(K5:K16) -> 90697.624
A18: CFF
A19: Purchases of investments | B19: -5009 | C19: 0 | D19: 0 | E19: -15262 | F19: 0 | G19: =F19 -> 0 | H19: =G19 -> 0 | I19: =H19 -> 0 | J19: =I19 -> 0 | K19: =J19 -> 0
A20: Purchases of property and equipment | B20: -6517 | C20: -4654 | D20: -6090 | E20: -5570 | F20: -5206 | G20: =-'Fixed asset schedule'!H4 -> -4186.3594 | H20: =-'Fixed asset schedule'!I4 -> -4003.5396 | I20: =-'Fixed asset schedule'!J4 -> -3828.7037 | J20: =-'Fixed asset schedule'!K4 -> -3661.503 | K20: =-'Fixed asset schedule'!L4 -> -3501.6039
A21: Payments for acquisitions, net of cash acquired | B21: -213057 | C21: -253961 | D21: 0 | E21: -355250 | F21: -852702
A22: Net cash flows (used in) from investing activities | B22: -207293 | C22: -250335 | D22: 21992 | E22: -360382 | F22: -857908 | G22: =SUM(G19:G21) -> -4186.3594 | H22: =SUM(H19:H21) -> -4003.5396 | I22: =SUM(I19:I21) -> -3828.7037 | J22: =SUM(J19:J21) -> -3661.503 | K22: =SUM(K19:K21) -> -3501.6039
A23: CFI
A24: Proceeds from equity plans | B24: 11099 | C24: 15033 | D24: 16165 | E24: 25956 | F24: 27761 | G24: =F24 -> 27761 | H24: =G24 -> 27761 | I24: =H24 -> 27761 | J24: =I24 -> 27761 | K24: =J24 -> 27761
A25: Repurchases of common stock | B25: -60000 | C25: -35000 | D25: -77041 | E25: -33962 | F25: -86777 | G25: 0 | H25: 0 | I25: 0 | J25: 0 | K25: 0
A26: Proceeds from issuance of convertible senior notes | B26: 0 | C26: 350100 | D26: 0 | E26: 0 | F26: 438750 | G26: 0 | H26: 0 | I26: 0 | J26: 0 | K26: 0
A27: Purchase of capped calls | B27: 0 | C27: -43056 | D27: 0 | E27: 0 | F27: -42210 | G27: 0 | H27: 0 | I27: 0 | J27: 0 | K27: 0
A28: Dividend payments to stockholders | B28: -29900 | C28: -31561 | D28: -31063 | E28: -31554 | F28: -31460 | G28: =F28 -> -31460 | H28: =G28 -> -31460 | I28: =H28 -> -31460 | J28: =I28 -> -31460 | K28: =J28 -> -31460
A29: Proceeds from the issuance of debt | B29: 98500 | C29: 0 | D29: 7475 | E29: 195000 | F29: 730000 | G29: 0 | H29: 0 | I29: 0 | J29: 0 | K29: 0
A30: Repayment of revolving line of credit | B30: 0 | C30: 0 | D30: 0 | E30: -85000 | F30: -110000 | G30: =-'Debt Schedule'!C12 -> 0 | H30: =-'Debt Schedule'!D12 -> 0 | I30: =-'Debt Schedule'!E12 -> 0 | J30: =-'Debt Schedule'!F12 -> 0 | K30: =-'Debt Schedule'!G12 -> 0
A31: Principal payment on term loan | B31: -11288 | C31: -117313 | D31: -6873 | E31: -6875 | F31: -261250 | G31: =-'Debt Schedule'!C5 -> -17028.525 | H31: =-'Debt Schedule'!D5 -> -17028.525 | I31: =-'Debt Schedule'!E5 -> -17028.525 | J31: =-'Debt Schedule'!F5 -> -17028.525 | K31: =-'Debt Schedule'!G5 -> -17028.525
A32: Payment of credit facility debt issuance costs | B32: 0 | C32: -904 | D32: -2262 | E32: 0 | F32: -6821
A33: Net cash flows from (used in) financing activities | B33: 3080 | C33: 132113 | D33: -101423 | E33: 51188 | F33: 640823 | G33: =SUM(G24:G32) -> -20727.525 | H33: =SUM(H24:H32) -> -20727.525 | I33: =SUM(I24:I32) -> -20727.525 | J33: =SUM(J24:J32) -> -20727.525 | K33: =SUM(K24:K32) -> -20727.525
A35: Effect of exchange rate changes on cash | B35: 3097 | C35: -2892 | D35: -11858 | E35: 5955 | F35: -3290 | G35: 0 | H35: 0 | I35: 0 | J35: 0 | K35: 0
A36: Net (decrease) increase in cash and cash equivalents | B36: -56269 | C36: 57416 | D36: 100871 | E36: -129319 | F36: -8881 | G36: =G38-G37 -> -9447.599 | H36: =H38-H37 -> -55594.291 | I36: =I38-I37 -> 3716.5585 | J36: =J38-J37 -> -6372.3117 | K36: =K38-K37 -> 16089.139
A37: Cash and cash equivalents, beginning of year | B37: 154259 | C37: 97990 | D37: 155406 | E37: 256277 | F37: 126958 | G37: =F38 -> 118077 | H37: =G38 -> 108629.4 | I37: =H38 -> 53035.11 | J37: =I38 -> 56751.668 | K37: =J38 -> 50379.356
A38: Cash and cash equivalents, end of year | B38: 97990 | C38: 155406 | D38: 256277 | E38: 126958 | F38: 118077 | G38: =G33+G22+G17 -> 108629.4 | H38: =H33+H22+H17 -> 53035.11 | I38: =I33+I22+I17 -> 56751.668 | J38: =J33+J22+J17 -> 50379.356 | K38: =K33+K22+K17 -> 66468.495

Sheet NWC
B1: Actual | F1: Projected
B2: 2021 | C2: =B2+1 -> 2022 | D2: =C2+1 -> 2023 | E2: =D2+1 -> 2024 | F2: =E2+1 -> 2025 | G2: =F2+1 -> 2026 | H2: =G2+1 -> 2027 | I2: =H2+1 -> 2028 | J2: =I2+1 -> 2029
A3: =BS!A5 -> Accounts receivable | B3: =BS!B5 -> 99815 | C3: =BS!C5 -> 97834 | D3: =BS!D5 -> 125825 | E3: =BS!E5 -> 163575 | F3: =(IS!G8*F22)/365 -> 177685.15 | G3: =(IS!H8*G22)/365 -> 194961.6 | H3: =(IS!I8*H22)/365 -> 212883.29 | I3: =(IS!J8*I22)/365 -> 232514.94 | J3: =(IS!K8*J22)/365 -> 254024.41
A5: =BS!A6 -> Unbilled receivables | B5: =BS!B6 -> 25816 | C5: =BS!C6 -> 29158 | D5: =BS!D6 -> 29965 | E5: =BS!E6 -> 34672 | F5: =(IS!G8*F23)/365 -> 41021.161 | G5: =IS!H8*G23/365 -> 45009.679 | H5: =IS!I8*H23/365 -> 49147.157 | I5: =IS!J8*I23/365 -> 53679.405 | J5: =IS!K8*J23/365 -> 58645.175
A7: =BS!A7 -> Other current assets | B7: =BS!B7 -> 56771 | C7: =BS!C7 -> 42784 | D7: =BS!D7 -> 48040 | E7: =BS!E7 -> 52489 | F7: =IS!G8*$F$8 -> 57951.65 | G7: =IS!H8*$F$8 -> 63586.332 | H7: =IS!I8*$F$8 -> 69431.452 | I7: =IS!J8*$F$8 -> 75834.276 | J7: =IS!K8*$F$8 -> 82849.548
F8: =$E$7/IS!$F$8 -> 0.069668666 | G8: =$E$7/IS!$F$8 -> 0.069668666 | H8: =$E$7/IS!$F$8 -> 0.069668666 | I8: =$E$7/IS!$F$8 -> 0.069668666 | J8: =$E$7/IS!$F$8 -> 0.069668666
A9: Total Current Non-Cash Assets | B9: =B3+B5+B7 -> 182402 | C9: =C3+C5+C7 -> 169776 | D9: =D3+D5+D7 -> 203830 | E9: =E3+E5+E7 -> 250736 | F9: =F3+F5+F7 -> 276657.96 | G9: =G3+G5+G7 -> 303557.62 | H9: =H3+H5+H7 -> 331461.9 | I9: =I3+I5+I7 -> 362028.62 | J9: =J3+J5+J7 -> 395519.14
A11: Current Liabilities
A12: =BS!A19 -> Accounts payable | B12: =BS!B19 -> 9683 | C12: =BS!C19 -> 9282 | D12: =BS!D19 -> 12371 | E12: =BS!E19 -> 13910 | F12: =IS!F16*F24/365 -> 16800.173 | G12: =IS!G16*G24/365 -> 17770.548 | H12: =IS!H16*H24/365 -> 18088.224 | I12: =IS!I16*I24/365 -> 19109.387 | J12: =IS!J16*J24/365 -> 20451.167
B13: =B12/IS!B16 -> 0.15589078 | C13: =C12/IS!C16 -> 0.11831891 | D13: =D12/IS!D16 -> 0.13091559 | E13: =E12/IS!E16 -> 0.10989358 | F13: =AVERAGE($B$13:$E$13) -> 0.12875472 | G13: =AVERAGE($B$13:$E$13) -> 0.12875472 | H13: =AVERAGE($B$13:$E$13) -> 0.12875472 | I13: =AVERAGE($B$13:$E$13) -> 0.12875472 | J13: =AVERAGE($B$13:$E$13) -> 0.12875472
A14: ST Deferred Revenue | B14: =BS!B23 -> 205021 | C14: =BS!C23 -> 227670 | D14: =BS!D23 -> 236090 | E14: =BS!E23 -> 332142 | F14: =IS!G8*F15 -> 390954.46 | G14: =IS!H8*G15 -> 410713.33 | H14: =IS!I8*H15 -> 448467.8 | I14: =IS!J8*I15 -> 478939.58 | J14: =IS!K8*J15 -> 523245.28
B15: =B14/IS!B8 -> 0.46369106 | C15: =C14/IS!C8 -> 0.42850448 | D15: =D14/IS!D8 -> 0.39216761 | E15: =E14/IS!E8 -> 0.47828823 | F15: 0.47 | G15: 0.45 | H15: 0.45 | I15: 0.44 | J15: 0.44
A16: Accrued Expenses | B16: =BS!B20 -> 66607 | C16: =BS!C20 -> 59232 | D16: =BS!D20 -> 72058 | E16: =BS!E20 -> 99891 | F16: =IS!F21*F17 -> 94124.179 | G16: =IS!G21*G17 -> 108505.74 | H16: =IS!H21*H17 -> 119055.84 | I16: =IS!I21*I17 -> 129999.95 | J16: =IS!J21*J17 -> 141988.27
B17: =B16/IS!B21 -> 0.66531819 | C17: =C16/IS!C21 -> 0.470506 | D17: =D16/IS!D21 -> 0.511921 | E17: =E16/IS!E21 -> 0.64001512 | F17: =AVERAGE($B$17:$E$17) -> 0.57194008 | G17: =AVERAGE($B$17:$E$17) -> 0.57194008 | H17: =AVERAGE($B$17:$E$17) -> 0.57194008 | I17: =AVERAGE($B$17:$E$17) -> 0.57194008 | J17: =AVERAGE($B$17:$E$17) -> 0.57194008
A19: Total Current Non-Debt Liabilities | B19: =B12+B14+B16 -> 281311 | C19: =C12+C14+C16 -> 296184 | D19: =D12+D14+D16 -> 320519 | E19: =E12+E14+E16 -> 445943 | F19: =F12+F14+F16 -> 501878.81 | G19: =G12+G14+G16 -> 536989.62 | H19: =H12+H14+H16 -> 585611.87 | I19: =I12+I14+I16 -> 628048.91 | J19: =J12+J14+J16 -> 685684.72
A22: Receivable Days | B22: =B3/IS!B8*365 -> 82.398451 | C22: =C3/IS!C8*365 -> 67.209743 | D22: =D3/IS!D8*365 -> 76.287597 | E22: =E3/IS!E8*365 -> 85.975694 | F22: =AVERAGE($B$22:$E$22) -> 77.967871 | G22: =AVERAGE($B$22:$E$22) -> 77.967871 | H22: =AVERAGE($B$22:$E$22) -> 77.967871 | I22: =AVERAGE($B$22:$E$22) -> 77.967871 | J22: =AVERAGE($B$22:$E$22) -> 77.967871
A23: Unbilled Receivable Days | B23: =B5/IS!B8*365 -> 21.31141 | C23: =C5/IS!C8*365 -> 20.030886 | D23: =D5/IS!D8*365 -> 18.167756 | E23: =E5/IS!E8*365 -> 18.223746 | F23: 18 | G23: 18 | H23: 18 | I23: 18 | J23: 18
A24: Payable Days | B24: =B12/IS!B16*365 -> 56.900135 | C24: =C12/IS!C16*365 -> 43.186401 | D24: =D12/IS!D16*365 -> 47.784192 | E24: =E12/IS!E16*365 -> 40.111158 | F24: =AVERAGE($B$24:$E$24) -> 46.995472 | G24: =AVERAGE($B$24:$E$24) -> 46.995472 | H24: =AVERAGE($B$24:$E$24) -> 46.995472 | I24: =AVERAGE($B$24:$E$24) -> 46.995472 | J24: =AVERAGE($B$24:$E$24) -> 46.995472
A26: Operational Net Working Capital | B26: =B9-B19 -> -98909 | C26: =C9-C19 -> -126408 | D26: =D9-D19 -> -116689 | E26: =E9-E19 -> -195207 | F26: =F9-F19 -> -225220.85 | G26: =G9-G19 -> -233432 | H26: =H9-H19 -> -254149.97 | I26: =I9-I19 -> -266020.29 | J26: =J9-J19 -> -290165.58
A27: Change In NWC | C27: =C26-B26 -> -27499 | D27: =D26-C26 -> 9719 | E27: =E26-D26 -> -78518 | F27: =F26-E26 -> -30013.852 | G27: =G26-F26 -> -8211.1488 | H27: =H26-G26 -> -20717.969 | I27: =I26-H26 -> -11870.321 | J27: =J26-I26 -> -24145.293
A29: Out of NWC adjustment
A30: Other Assets | B30: =BS!B15 -> 8915 | C30: =BS!C15 -> 12832 | D30: =BS!D15 -> 8255 | E30: =BS!E15 -> 12693 | F30: =IS!G8*NWC!F31 -> 13897.403 | G30: =IS!H8*NWC!G31 -> 15248.658 | H30: =IS!I8*NWC!H31 -> 16650.378 | I30: =IS!J8*NWC!I31 -> 18185.841 | J30: =IS!K8*NWC!J31 -> 19868.176
A31: % Revenue | B31: =B30/IS!C8 -> 0.016779187 | C31: =C30/IS!D8 -> 0.021315154 | D31: =D30/IS!E8 -> 0.011887293 | E31: =E30/IS!F8 -> 0.016847423 | F31: =AVERAGE($B$31:$E$31) -> 0.016707264 | G31: =AVERAGE($B$31:$E$31) -> 0.016707264 | H31: =AVERAGE($B$31:$E$31) -> 0.016707264 | I31: =AVERAGE($B$31:$E$31) -> 0.016707264 | J31: =AVERAGE($B$31:$E$31) -> 0.016707264
A32: Change in Other Assets | C32: =B30-C30 -> -3917 | D32: =C30-D30 -> 4577 | E32: =D30-E30 -> -4438 | F32: =E30-F30 -> -1204.4031 | G32: =F30-G30 -> -1351.2548 | H32: =G30-H30 -> -1401.7201 | I32: =H30-I30 -> -1535.463 | J32: =I30-J30 -> -1682.3345

Sheet Fixed asset schedule
B2: PP&E | C2: 2020 | D2: 2021 | E2: =D2+1 -> 2022 | F2: =E2+1 -> 2023 | G2: 2024 | H2: =G2+1 -> 2025 | I2: =H2+1 -> 2026 | J2: =I2+1 -> 2027 | K2: =J2+1 -> 2028 | L2: =K2+1 -> 2029
B3: Beginning balance | D3: =C6 -> 14345 | E3: =D6 -> 14927 | F3: =E6 -> 15225 | G3: =F6 -> 13746 | H3: =G6 -> 12526 | I3: =H6 -> 11978.985 | J3: =I6 -> 11455.859 | K3: =J6 -> 10955.578 | L3: =K6 -> 10477.144
B4: Purchases | D4: =-CFS!C20 -> 4654 | E4: =-CFS!D20 -> 6090 | F4: =-CFS!E20 -> 5570 | G4: =-CFS!F20 -> 5206 | H4: =H5*H10 -> 4186.3594 | I4: =I5*I10 -> 4003.5396 | J4: =J5*J10 -> 3828.7037 | K4: =K5*K10 -> 3661.503 | L4: =L5*L10 -> 3501.6039
B5: Depreciation | D5: =CFS!C5 -> 5477 | E5: =CFS!D5 -> 5002 | F5: =CFS!E5 -> 6345 | G5: =CFS!F5 -> 6426 | H5: =H3*H11 -> 4733.3739 | I5: =I3*I11 -> 4526.6659 | J5: =J3*J11 -> 4328.9849 | K5: =K3*K11 -> 4139.9367 | L5: =L3*L11 -> 3959.1443
B6: Ending balance | C6: =BS!B10 -> 14345 | D6: =BS!C10 -> 14927 | E6: =BS!D10 -> 15225 | F6: =BS!E10 -> 13746 | G6: =G3+G4-G5 -> 12526 | H6: =H3+H4-H5 -> 11978.985 | I6: =I3+I4-I5 -> 11455.859 | J6: =J3+J4-J5 -> 10955.578 | K6: =K3+K4-K5 -> 10477.144 | L6: =L3+L4-L5 -> 10019.604
B9: %CapEx | D9: =D4/IS!C8 -> 0.0087594318 | E9: =E4/IS!D8 -> 0.010116061 | F9: =F4/IS!E8 -> 0.0080208629 | G9: =G4/IS!F8 -> 0.0069099254 | H9: =AVERAGE($D$9:$F$9) -> 0.0089654518 | I9: =AVERAGE($D$9:$F$9) -> 0.0089654518 | J9: =AVERAGE($D$9:$F$9) -> 0.0089654518 | K9: =AVERAGE($D$9:$F$9) -> 0.0089654518 | L9: =AVERAGE($D$9:$F$9) -> 0.0089654518
B10: %Depr CapEx Maintenance | D10: =MIN(D4, D5)/D5 -> 0.84973526 | E10: =MIN(E4, E5)/E5 -> 1 | F10: =MIN(F4, F5)/F5 -> 0.87785658 | G10: =MIN(G4, G5)/G5 -> 0.81014628 | H10: =AVERAGE($D$10:$G$10) -> 0.88443453 | I10: =AVERAGE($D$10:$G$10) -> 0.88443453 | J10: =AVERAGE($D$10:$G$10) -> 0.88443453 | K10: =AVERAGE($D$10:$G$10) -> 0.88443453 | L10: =AVERAGE($D$10:$G$10) -> 0.88443453
B11: %Depreciation | D11: =D5/D3 -> 0.38180551 | E11: =E5/E3 -> 0.33509747 | F11: =F5/F3 -> 0.41674877 | G11: =AVERAGE($D$11:$F$11) -> 0.37788392 | H11: =AVERAGE($D$11:$F$11) -> 0.37788392 | I11: =AVERAGE($D$11:$F$11) -> 0.37788392 | J11: =AVERAGE($D$11:$F$11) -> 0.37788392 | K11: =AVERAGE($D$11:$F$11) -> 0.37788392 | L11: =AVERAGE($D$11:$F$11) -> 0.37788392
B14: Intangible assets
B15: Beginning balance | D15: =C18 -> 287185 | E15: =D18 -> 217355 | F15: =E18 -> 354278 | G15: =F18 -> 723571 | H15: =G18 -> 1479655 | I15: =H18 -> 1422109 | J15: =I18 -> 1372462.5 | K15: =J18 -> 1330337.3 | L15: =K18 -> 1295629.6
B16: Purchases | D16: =(D18-D15)+D17 -> -22323 | E16: =(E18-E15)+E17 -> 206653 | F16: =(F18-F15)+F17 -> 466095 | G16: =(G18-G15)+G17 -> 852702 | H16: =IS!G8*H20 -> 41590.9 | I16: =IS!H8*I20 -> 45634.814 | J16: =IS!I8*J20 -> 49829.756 | K16: =IS!J8*K20 -> 54424.952 | L16: =IS!K8*L20 -> 59459.691
B17: Amortization | D17: =CFS!C7 -> 47507 | E17: =CFS!D7 -> 69730 | F17: =CFS!E7 -> 96802 | G17: =CFS!F7 -> 96618 | H17: =H15*H22 -> 99136.885 | I17: =I15*I22 -> 95281.304 | J17: =J15*J22 -> 91954.989 | K17: =K15*K22 -> 89132.599 | L17: =L15*L22 -> 86807.186
B18: Ending balance | C18: =BS!B11 -> 287185 | D18: =BS!C11 -> 217355 | E18: =BS!D11 -> 354278 | F18: =BS!E11 -> 723571 | G18: =G15+G16-G17 -> 1479655 | H18: =H15+H16-H17 -> 1422109 | I18: =I15+I16-I17 -> 1372462.5 | J18: =J15+J16-J17 -> 1330337.3 | K18: =K15+K16-K17 -> 1295629.6 | L18: =L15+L16-L17 -> 1268282.1
B20: %CapEx | D20: =D16/IS!C8 -> -0.042014782 | E20: =E16/IS!D8 -> 0.34327 | F20: =F16/IS!E8 -> 0.67118206 | G20: =G16/IS!F8 -> 1.1317916 | H20: 0.05 | I20: 0.05 | J20: 0.05 | K20: 0.05 | L20: 0.05
B21: %Rev CapEx Growth | D21: =MAX(0, D16-D17)/IS!C8 -> 0 | E21: =MAX(0, E16-E17)/IS!D8 -> 0.22744193 | F21: =MAX(0, F16-F17)/IS!E8 -> 0.53178609 | G21: =MAX(0, G16-G17)/IS!F8 -> 1.0035505
B22: %Depreciation | D22: =D17/D15 -> 0.16542299 | E22: =E17/E15 -> 0.32081158 | F22: =F17/F15 -> 0.2732374 | G22: =G17/G15 -> 0.1335294 | H22: 0.067 | I22: 0.067 | J22: 0.067 | K22: 0.067 | L22: 0.067
